Workbook

Sheet record
A1: fcc | B1: epscc | C1: fcu | D1: epscu | E1: Vn | F1: Vst
A2: =Calculate!Q3 -> 88.200889 | B2: =Calculate!R3 -> 0.0030251111 | C2: =Calculate!S3 -> 0.017611077 | D2: =Calculate!T3 -> 0.015084183 | E2: =Calculate!Q6 -> 252481.2 | F2: =Calculate!R6 -> 656250000

Sheet Calculate
B1: Load is applied along the width axis
G2: Rebar | I2: Diameter(inch) | J2: Diameter(mm) | K2: Area(mm^2) | Q2: fcc | R2: epscc | S2: fcu | T2: epscu
B3: Section | G3: 8mm | H3: 8mm | I3: =8/25.4 -> 0.31496063 | J3: =8 -> 8 | K3: =PI()*J3^2/4 -> 50.265482 | Q3: =I39 -> 88.200889 | R3: =I40 -> 0.0030251111 | S3: =I43 -> 0.017611077 | T3: =I42 -> 0.015084183
B4: Width(y) | D4: 250 | G4: #4 | H4: D13 | I4: =4/8 -> 0.5 | J4: =I4*25.4 -> 12.7 | K4: =PI()*J4^2/4 -> 126.67687
B5: Depth(z) | D5: 250 | G5: #5 | H5: D16 | I5: =5/8 -> 0.625 | J5: =I5*25.4 -> 15.875 | K5: =PI()*J5^2/4 -> 197.93261 | Q5: Vn | R5: Vst
B6: Clear cover (y) | D6: 30 | G6: 20mm | H6: 20mm | I6: =20/25.4 -> 0.78740157 | J6: =20 -> 20 | K6: =PI()*J6^2/4 -> 314.15927 | Q6: =D40 -> 252481.2 | R6: =D41 -> 656250000
B7: Clear cover (z) | D7: 30 | G7: #7 | H7: D22 | I7: =7/8 -> 0.875 | J7: =I7*25.4 -> 22.225 | K7: =PI()*J7^2/4 -> 387.94791
G8: #8 | H8: D25 | I8: =8/8 -> 1 | J8: =I8*25.4 -> 25.4 | K8: =PI()*J8^2/4 -> 506.70748
B9: Transverse Reinforcement
B10: spacing | D10: 150 | G10: z reinforcement | I10: # | J10: Type | Q10: mm-s-N-Mpa
B11: Tr. Hoop Rebar | D11: 8mm | I11: 4 | J11: 8mm | L11: w | M11: w-db | N11: (w-db)^2 | Q11: inches | R11: 25.4
B12: fy Hoop (Mpa) | D12: 430 | J12: #4 | L12: =154/3 -> 51.333333 | M12: =L12-VLOOKUP($D$22, $G$3:$K$8, 4, FALSE) -> 31.333333 | N12: =M12^2 -> 981.77778 | Q12: feet | R12: 304.8
B13: # of hoop in a bundle | D13: 1 | J13: #5 | L13: =154/3 -> 51.333333 | M13: =L13-VLOOKUP($D$22, $G$3:$K$8, 4, FALSE) -> 31.333333 | N13: =M13^2 -> 981.77778 | Q13: ksi | R13: 6.8947591
B14: Clear distance | D14: =D10-D13*VLOOKUP(D11,G3:K8,4,FALSE) -> 142 | L14: =154/3 -> 51.333333 | M14: =L14-VLOOKUP($D$22, $G$3:$K$8, 4, FALSE) -> 31.333333 | N14: =M14^2 -> 981.77778 | Q14: psi | R14: 0.0068947573
B15: Width (core) | D15: =D4-2*D7-VLOOKUP(D11, G3:K8, 4,FALSE ) -> 182 | G15: y reinforcement | I15: # | J15: Type | L15: =154/3 -> 51.333333 | M15: =L15-VLOOKUP($D$22, $G$3:$K$8, 4, FALSE) -> 31.333333 | N15: =M15^2 -> 981.77778 | Q15: kgf/cm2 | R15: 0.09807
B16: Depth (core) | D16: =D5-2*D6-VLOOKUP(D11, G3:K8, 4,FALSE ) -> 182 | I16: 4 | J16: 8mm | L16: =154/3 -> 51.333333 | M16: =L16-VLOOKUP($D$22, $G$3:$K$8, 4, FALSE) -> 31.333333 | N16: =M16^2 -> 981.77778
B17: Area in a bundle | D17: =D13*VLOOKUP(D11,G3:K8,5,FALSE) -> 50.265482 | J17: #4 | L17: =154/3 -> 51.333333 | M17: =L17-VLOOKUP($D$22, $G$3:$K$8, 4, FALSE) -> 31.333333 | N17: =M17^2 -> 981.77778
B18: Area of core | D18: =D15*D16 -> 33124 | J18: #5 | L18: =154/3 -> 51.333333 | M18: =L18-VLOOKUP($D$22, $G$3:$K$8, 4, FALSE) -> 31.333333 | N18: =M18^2 -> 981.77778
L19: =154/3 -> 51.333333 | M19: =L19-VLOOKUP($D$22, $G$3:$K$8, 4, FALSE) -> 31.333333 | N19: =M19^2 -> 981.77778
G20: Concrete | L20: =154/3 -> 51.333333 | M20: =L20-VLOOKUP($D$22, $G$3:$K$8, 4, FALSE) -> 31.333333 | N20: =M20^2 -> 981.77778
B21: Longitudinal Reinforcement | G21: fc (Mpa) | I21: 80 | L21: =154/3 -> 51.333333 | M21: =L21-VLOOKUP($D$22, $G$3:$K$8, 4, FALSE) -> 31.333333 | N21: =M21^2 -> 981.77778
B22: Long. Rebar | D22: 20mm | G22: eps0 | I22: 0.002 | L22: =154/3 -> 51.333333 | M22: =L22-VLOOKUP($D$22, $G$3:$K$8, 4, FALSE) -> 31.333333 | N22: =M22^2 -> 981.77778
B23: # of bars | D23: 12 | G23: epss | I23: 0.005 | L23: =154/3 -> 51.333333 | M23: =L23-VLOOKUP($D$22, $G$3:$K$8, 4, FALSE) -> 31.333333 | N23: =M23^2 -> 981.77778
B24: fy | D24: 430 | G24: Ec | I24: =15000*SQRT(I21*100/9.8)*0.8*9.8/100 -> 33600
B25: As | D25: =D23*VLOOKUP(D22, G3:K8, 5,FALSE ) -> 3769.9112
B26: rho_cc | D26: =D25/D18 -> 0.11381208 | G26: Mander's Model
B27: rho | D27: =D25/D4/D5 -> 0.060318579 | G27: Ae | I27: =(D18-SUM(N:N)/6)*(1-D14/2/D16)*(1-D14/2/D15) -> 11590.624
G28: ke | I28: =I27/(1-D26)/D18 -> 0.39485553
G29: rho_tz | I29: =(I11*VLOOKUP(J11, G3:K8, 5, FALSE) + I12*VLOOKUP(J12, G3:K8, 5, FALSE) + I13*VLOOKUP(J13, G3:K8, 5, FALSE))/D16/D10 -> 0.0073649059
B30: poisson | C30: 0.2 | G30: rho_ty | I30: =(I16*VLOOKUP(J16, G3:K8, 5, FALSE) + I17*VLOOKUP(J17, G3:K8, 5, FALSE)+ I18*VLOOKUP(J18, G3:K8, 5, FALSE))/D15/D10 -> 0.0073649059
B31: Shear Capacity | G31: rho_t | I31: =I29+I30 -> 0.014729812
B32: G | D32: =I24/(2*(1+C30)) -> 14000 | G32: flz | I32: =I28*I29*$D$12 -> 1.2504717
B33: rhotfyh | D33: =IF(I31*D12>2.42, 2.42, I31*D12) -> 2.42 | E33: =D12*I31 -> 6.333819 | G33: fly | I33: =I28*I30*D12 -> 1.2504717
B34: fv1 | D34: =IF(D33/12.5+0.305-0.083*3<0.0025, 0.0025, IF(D33/12.5+0.305-0.083*3>0.25, 0.25, D33/12.5+0.305-0.083*3)) -> 0.2496 | E34: =D33/12.5+0.305-0.083*3 -> 0.2496 | G34: xfactor | I34: =(I32+I33)/2/I21 -> 0.015630897
B35: ALR | D35: =0.0867*(D4*D5)*I21/13.8/(D4*D5) -> 0.5026087 | G35: rfactor | I35: =MIN(I32, I33)/MAX(I32, I33) -> 1
B36: fv2 | D36: =IF(1+D35>1.5, 1.5, 1+D35) -> 1.5 | E36: =1+D35 -> 1.5026087 | G36: Afactor | I36: =6.8886-(0.6069+17.275*I35)*EXP(1)^(-4.989*I35) -> 6.76678
B37: vc | D37: =IF(D34*D36*SQRT(I21)>0.33*SQRT(I21), 0.33*SQRT(I21), D34*D36*SQRT(I21)) -> 2.9516097 | G37: Bfactor | I37: =4.5/(5/I36*(0.9849-0.6306*EXP(1)^(-3.989*I35))-0.1)-5 -> 2.2684066
B38: Vc | D38: =0.8*D4*D5*D37 -> 147580.49 | G38: Kfactor | I38: =1+I36*I34*(0.1+0.9/(1+I37*I34)) -> 1.1025111
B39: Vs | D39: =(I11*VLOOKUP(J11, G3:K8, 5, FALSE) + I12*VLOOKUP(J12, G3:K8, 5, FALSE) + I13*VLOOKUP(J13, G3:K8, 5, FALSE))*D12*D15/D10 -> 104900.71 | G39: fcc | I39: =I21*I38 -> 88.200889
B40: Vn | D40: =D38+D39 -> 252481.2 | G40: epscc | I40: =I22*(1+5*(I39/I21-1)) -> 0.0030251111
...
